Workbook

Sheet 新内核总表
A1: 分区/域 | B1: 组件 | C1: 端 | D1: 应有文件 | E1: Codex 状态 | F1: 完成度 | G1: 备注
A2: 核心模型/规划 | B2: 统一数据模型(对象/清单/哈希) | C2: 共享 | D2: CanonicalCore.swift | E2: ✅ 已写 | F2: 1 | G2: 1396行
A3: 核心模型/规划 | B3: diff/LWW 规划 | C3: 共享 | D3: CanonicalSyncPlanner.swift | E3: ✅ 已写 | F3: 1
A4: 核心模型/规划 | B4: apply 计划 / 运行时 | C4: 共享 | D4: CanonicalApplyPlan.swift / CanonicalApplyRuntime.swift | E4: ✅ 已写 | F4: 1
A5: 核心模型/规划 | B5: 同步运行时(决策叠加) | C5: 共享 | D5: CanonicalSyncRuntime.swift | E5: ✅ 已写 | F5: 1 | G5: 运行时主决策仅3 scope
A6: 核心模型/规划 | B6: 库同步规划 / 冲突解决 | C6: 共享 | D6: CanonicalLibrarySyncPlanner.swift / CanonicalConflictResolver.swift | E6: ✅ 已写 | F6: 1
A7: 核心模型/规划 | B7: 投影 / 契约 / 库对象 | C7: 共享 | D7: CanonicalObjectProjection / CanonicalProjectionContract / CanonicalLibraryObject.swift | E7: ✅ 已写 | F7: 1
A8: 域·录音元数据 | B8: 共享 cutover / 执行影子 | C8: 共享 | D8: CanonicalRecordingMetadataCutover.swift / CanonicalRecordingMetadataExecutionShadow.swift | E8: ✅ 已写 | F8: 1
A9: 域·录音元数据 | B9: NoCommit 执行器 | C9: iPhone | D9: IPhoneRecordingMetadataNoCommitExecutor.swift | E9: ✅ 已写 | F9: 1
A10: 域·录音元数据 | B10: Cutover 执行器 | C10: iPhone | D10: IPhoneRecordingMetadataCutoverExecutor.swift | E10: ✅ 已写 | F10: 1
A11: 域·录音元数据 | B11: 真实 ApplyPort | C11: iPhone | D11: IPhoneRecordingMetadataRealApplyPort.swift | E11: ❌ 缺 | F11: 0 | G11: ★承重·未写
A12: 域·录音元数据 | B12: 读侧 Seam | C12: iPhone | D12: IPhoneRecordingMetadataReadSideSeam.swift | E12: ❌ 缺 | F12: 0 | G12: ★承重·未写
A13: 域·录音元数据 | B13: NoCommit 执行器 | C13: Mac | D13: MacRecordingMetadataNoCommitExecutor.swift | E13: ✅ 已写 | F13: 1
A14: 域·录音元数据 | B14: Cutover 执行器 | C14: Mac | D14: MacRecordingMetadataCutoverExecutor.swift | E14: ✅ 已写 | F14: 1
A15: 域·录音元数据 | B15: 真实 ApplyPort | C15: Mac | D15: MacRecordingMetadataRealApplyPort.swift | E15: ❌ 缺 | F15: 0 | G15: ★承重·未写
A16: 域·录音元数据 | B16: 读侧 Seam | C16: Mac | D16: MacRecordingMetadataReadSideSeam.swift | E16: ❌ 缺 | F16: 0 | G16: ★承重·未写
A17: 域·录音元数据 | B17: 漏传:入站录音 + 应用桥 | C17: Mac | D17: IncomingRecordingMetadata.swift / CanonicalRecordingManifestApplyBridge(SecureLocalHTTPSServer) | E17: 🟡 门控 | F17: 0.5 | G17: 已接但默认off,切canonical才生效;需真机确认落地
A18: 域·库元数据 | B18: 共享 cutover/读投影/landing/canary/observation/evidence | C18: 共享 | D18: CanonicalLibraryMetadata{Cutover,ReadProjection,Landing,ProductionCanary,Observation,PilotEvidence}.swift | E18: ✅ 已写 | F18: 1 | G18: 最完整的域
A19: 域·库元数据 | B19: NoCommit / Cutover / ReadSeam / RealApplyPort / CanaryBootstrap | C19: iPhone | D19: IPhoneLibraryMetadata{NoCommit,Cutover,ReadSideSeam,RealApplyPort,ProductionCanaryBootstrap}.swift | E19: ✅ 已写 | F19: 1 | G19: 四件齐+bootstrap
A20: 域·库元数据 | B20: NoCommit / Cutover / ReadSeam / RealApplyPort / CanaryBootstrap | C20: Mac | D20: MacLibraryMetadata{NoCommit,Cutover,ReadSideSeam,RealApplyPort,ProductionCanaryBootstrap}.swift | E20: ✅ 已写 | F20: 1 | G20: 四件齐+bootstrap
A21: 域·生成产物 | B21: 共享 cutover/guardedCommit/读投影 | C21: 共享 | D21: CanonicalGeneratedArtifact{Cutover,GuardedCommit,ReadProjection}.swift | E21: ✅ 已写 | F21: 1
A22: 域·生成产物 | B22: NoCommit / Cutover / ReadSeam / RealApplyPort | C22: iPhone | D22: IPhoneGeneratedArtifact{NoCommit,Cutover,ReadSideSeam,RealApplyPort}.swift | E22: ✅ 已写 | F22: 1 | G22: 四件齐
A23: 域·生成产物 | B23: NoCommit / Cutover / ReadSeam / RealApplyPort | C23: Mac | D23: MacGeneratedArtifact{NoCommit,Cutover,ReadSideSeam,RealApplyPort}.swift | E23: ✅ 已写 | F23: 1 | G23: 四件齐
A24: 域·墓碑/冲突 | B24: 共享 cutover/guardedCommit/读投影 | C24: 共享 | D24: CanonicalTombstoneConflict{Cutover,GuardedCommit,ReadProjection}.swift | E24: ✅ 已写 | F24: 1
A25: 域·墓碑/冲突 | B25: NoCommit / Cutover / ReadSeam / RealApplyPort | C25: iPhone | D25: IPhoneTombstoneConflict{NoCommit,Cutover,ReadSideSeam,RealApplyPort}.swift | E25: ✅ 已写 | F25: 1 | G25: 四件齐
A26: 域·墓碑/冲突 | B26: NoCommit / Cutover / ReadSeam / RealApplyPort | C26: Mac | D26: MacTombstoneConflict{NoCommit,Cutover,ReadSideSeam,RealApplyPort}.swift | E26: ✅ 已写 | F26: 1 | G26: 四件齐
A27: 域·音频上传 | B27: 共享 cutover/commit/状态真相/状态机 | C27: 共享 | D27: CanonicalAudioUploadCutover.swift / CanonicalAudioUploadRuntimeCommit.swift / CanonicalUploadStateTruth.swift / CanonicalTransferStateMachine.swift | E27: ✅ 已写 | F27: 1 | G27: 模型齐(非执行)
A28: 域·音频上传 | B28: NoCommit 执行器 + runtime 适配器 | C28: iPhone | D28: IPhoneAudioUploadNoCommitExecutor.swift / IPhoneCanonicalAudioUploadRuntimeAdapter.swift | E28: ✅ 已写 | F28: 1
A29: 域·音频上传 | B29: 真实 commit/cutover 执行器 + 协议 | C29: iPhone | D29: IPhoneAudioUploadCutoverExecutor.swift + protocol CanonicalAudioUploadCutoverExecutor | E29: ❌ 缺 | F29: 0 | G29: ★承重·未写(只有NoCommit)
A30: 域·音频上传 | B30: NoCommit 执行器 | C30: Mac | D30: MacAudioUploadNoCommitExecutor.swift | E30: ✅ 已写 | F30: 1
A31: 域·音频上传 | B31: 真实 commit/cutover 执行器 | C31: Mac | D31: MacAudioUploadCutoverExecutor.swift | E31: ❌ 缺 | F31: 0 | G31: ★承重·未写
A32: 文件层 | B32: 文件运行时 / 真实根原子写 / 生产执行 | C32: 共享 | D32: CanonicalFileRuntime.swift / CanonicalRootBoundMetadataWrite.swift / CanonicalProductionExecution.swift | E32: ✅ 已写 | F32: 1
A33: 文件层 | B33: 生产文件端口 | C33: iPhone | D33: IPhoneCanonicalProductionFilePort.swift | E33: 🟡 dry-run | F33: 0.5 | G33: 默认isDryRunOnly=true
A34: 文件层 | B34: 生产文件端口 | C34: Mac | D34: MacCanonicalProductionFilePort.swift | E34: 🟡 dry-run | F34: 0.5 | G34: 默认dry-run
A35: 文件层 | B35: 影子文件端口 | C35: 双端 | D35: IPhone/MacCanonicalShadowFilePort.swift | E35: ✅ 已写 | F35: 1
A36: 连接层 | B36: 传输运行时 / 只读探针 / 端口契约 | C36: 共享 | D36: CanonicalTransportRuntime.swift / CanonicalReadOnlyTransportProbe.swift / CanonicalProductionPorts.swift | E36: 🟡 影子 | F36: 0.5 | G36: 传输runtime空壳;Path B保留legacy
A37: 连接层 | B37: 生产传输端口(sendRequest) | C37: 双端 | D37: IPhone/MacCanonicalProductionTransportPort.swift | E37: 🟡 抑制 | F37: 0.5 | G37: sendRequest throw;Path B不需要
A38: 连接层 | B38: 影子/探针传输 | C38: 双端 | D38: IPhone/MacCanonicalShadow+LiveReadOnlyTransportProbe | E38: ✅ 已写 | F38: 1
A39: 连接层 | B39: legacy 连接(TLS/配对/HMAC) | C39: 双端 | D39: SecureLocalHTTPSServer/RequestVerifier/PairingManager/SelfSignedCertificateBuilder/SecureMacUploadClient | E39: ⏸ 保留 | G39: 可靠安全,Path B勿重写
A40: 上传runtime层 | B40: 上传运行时 / 状态机 / 状态真相 | C40: 共享 | D40: CanonicalUploadRuntime.swift / CanonicalTransferStateMachine.swift / CanonicalUploadStateTruth.swift | E40: 🟡 部分 | F40: 0.5 | G40: runtime空壳;状态模型齐
...

Sheet 未完成-按顺序
A1: 顺序 | B1: 项(★=承重) | C1: 端/范围 | D1: 要建/改文件 | E1: 抄哪个样板 | F1: 验收(真机证据) | G1: 依赖
A2: 1 | B2: ★录音域 RealApplyPort | C2: 双端(2文件) | D2: IPhoneRecordingMetadataRealApplyPort.swift / MacRecordingMetadataRealApplyPort.swift | E2: IPhoneLibraryMetadataRealApplyPort.swift 整份 | F2: 录音域测试根 N=1 真写+回滚;域矩阵 readyToRetireLegacy | G2: 无(最该先做)
A3: 2 | B3: ★录音域 ReadSideSeam | C3: 双端(2文件) | D3: IPhoneRecordingMetadataReadSideSeam.swift / MacRecordingMetadataReadSideSeam.swift | E3: IPhoneLibraryMetadataReadSideSeam.swift | F3: 录音读侧影子等价(canonical==legacy),0 divergence | G3: 无
A4: 3 | B4: ★音频 commit 执行器 + 协议 | C4: 双端 + 共享协议 | D4: IPhoneAudioUploadCutoverExecutor.swift / MacAudioUploadCutoverExecutor.swift + protocol CanonicalAudioUploadCutoverExecutor | E4: IPhoneLibraryMetadataCutoverExecutor + 现成 CanonicalAudioUploadRuntimeExecutor.execute | F4: 测试根 N=1 commit+回滚;真机音频真传到对端落盘 | G4: ITEM(若Path A)真实上传端口
A5: 4 | B5: 卡顿收尾 + 真机确认 | C5: iPhone | D5: StudyLibrarySyncCoordinator.swift:把 makeSyncManifest 也移出主线程 | E5: 已有 nonisolated 后台结构 | F5: 真机 inventoryBuildDurationMs 明显下降、页面不卡 | G5: 无
A6: 5 | B6: 漏传真机确认 | C6: Mac | D6: (已接,门控)切到 canonical existence apply 后验证 | E6: — | F6: 真机:iPhone 新录音→Mac 入库;jsonl recordingsApplied>0 | G6: 录音域就绪
A7: 6 | B7: ★真实库切回证明(命门) | C7: 共享/Debug | D7: 接 driver 调 CanonicalSwitchBackRealisticRootHarness.run 于真实库副本 | E7: 已有 harness(CanonicalLegacyCompatibility.swift) | F7: 真实库副本『canonical写→切回legacy读』数据无损+崩溃恢复 | G7: 在灰度前必须
A8: 7 | B8: 生产文件端口转真写(P2) | C8: 双端 | D8: IPhone/MacCanonicalProductionFilePort.swift 开放 allowProductionRootWrites | E8: IPhoneLibraryMetadataRealApplyPort 的真写模式 | F8: 真实根 N=1 写+回滚(先备份) | G8: 1/2 就绪 + 真机灰度
A9: 8 | B9: 单一主开关收敛 + 状态一致(P2) | C9: 双端 UI | D9: IPhoneSettingsView/MacSettingsView 收敛;状态读统一走 canonical 投影 | E9: 现有 KernelSwitch + effectiveStudy* | F9: 设置只剩一个有效开关;双端状态不错位 | G9: 读切换
A10: — | B10: 不做(Path B) | C10: 双端 | D10: 生产传输端口 sendRequest / 生产上传端口真实化 | E10: — | F10: 保留 legacy TLS/HMAC 与 legacy 上传,勿重写 | G10: —

Sheet Summary
A1: 分区/域 | B1: 应建组件数 | C1: 已完成(加权) | D1: 完成度%
A2: 核心模型/规划 | B2: =COUNTIFS(新内核总表!$A$2:$A$200,A2,新内核总表!$F$2:$F$200,"<>") -> 6 | C2: =SUMIFS(新内核总表!$F$2:$F$200,新内核总表!$A$2:$A$200,A2) -> 6 | D2: =IF(B2=0,0,C2/B2) -> 1
A3: 域·录音元数据 | B3: =COUNTIFS(新内核总表!$A$2:$A$200,A3,新内核总表!$F$2:$F$200,"<>") -> 10 | C3: =SUMIFS(新内核总表!$F$2:$F$200,新内核总表!$A$2:$A$200,A3) -> 5.5 | D3: =IF(B3=0,0,C3/B3) -> 0.55
A4: 域·库元数据 | B4: =COUNTIFS(新内核总表!$A$2:$A$200,A4,新内核总表!$F$2:$F$200,"<>") -> 3 | C4: =SUMIFS(新内核总表!$F$2:$F$200,新内核总表!$A$2:$A$200,A4) -> 3 | D4: =IF(B4=0,0,C4/B4) -> 1
A5: 域·生成产物 | B5: =COUNTIFS(新内核总表!$A$2:$A$200,A5,新内核总表!$F$2:$F$200,"<>") -> 3 | C5: =SUMIFS(新内核总表!$F$2:$F$200,新内核总表!$A$2:$A$200,A5) -> 3 | D5: =IF(B5=0,0,C5/B5) -> 1
A6: 域·墓碑/冲突 | B6: =COUNTIFS(新内核总表!$A$2:$A$200,A6,新内核总表!$F$2:$F$200,"<>") -> 3 | C6: =SUMIFS(新内核总表!$F$2:$F$200,新内核总表!$A$2:$A$200,A6) -> 3 | D6: =IF(B6=0,0,C6/B6) -> 1
A7: 域·音频上传 | B7: =COUNTIFS(新内核总表!$A$2:$A$200,A7,新内核总表!$F$2:$F$200,"<>") -> 5 | C7: =SUMIFS(新内核总表!$F$2:$F$200,新内核总表!$A$2:$A$200,A7) -> 3 | D7: =IF(B7=0,0,C7/B7) -> 0.6
A8: 文件层 | B8: =COUNTIFS(新内核总表!$A$2:$A$200,A8,新内核总表!$F$2:$F$200,"<>") -> 4 | C8: =SUMIFS(新内核总表!$F$2:$F$200,新内核总表!$A$2:$A$200,A8) -> 3 | D8: =IF(B8=0,0,C8/B8) -> 0.75
A9: 连接层 | B9: =COUNTIFS(新内核总表!$A$2:$A$200,A9,新内核总表!$F$2:$F$200,"<>") -> 3 | C9: =SUMIFS(新内核总表!$F$2:$F$200,新内核总表!$A$2:$A$200,A9) -> 2 | D9: =IF(B9=0,0,C9/B9) -> 0.66666667
A10: 上传runtime层 | B10: =COUNTIFS(新内核总表!$A$2:$A$200,A10,新内核总表!$F$2:$F$200,"<>") -> 2 | C10: =SUMIFS(新内核总表!$F$2:$F$200,新内核总表!$A$2:$A$200,A10) -> 1 | D10: =IF(B10=0,0,C10/B10) -> 0.5
A11: 接口/门面/开关 | B11: =COUNTIFS(新内核总表!$A$2:$A$200,A11,新内核总表!$F$2:$F$200,"<>") -> 4 | C11: =SUMIFS(新内核总表!$F$2:$F$200,新内核总表!$A$2:$A$200,A11) -> 3.5 | D11: =IF(B11=0,0,C11/B11) -> 0.875
A12: 读运行时/UI | B12: =COUNTIFS(新内核总表!$A$2:$A$200,A12,新内核总表!$F$2:$F$200,"<>") -> 4 | C12: =SUMIFS(新内核总表!$F$2:$F$200,新内核总表!$A$2:$A$200,A12) -> 3.5 | D12: =IF(B12=0,0,C12/B12) -> 0.875
A13: 性能/inventory | B13: =COUNTIFS(新内核总表!$A$2:$A$200,A13,新内核总表!$F$2:$F$200,"<>") -> 1 | C13: =SUMIFS(新内核总表!$F$2:$F$200,新内核总表!$A$2:$A$200,A13) -> 0.5 | D13: =IF(B13=0,0,C13/B13) -> 0.5
A14: 迁移脚手架 | B14: =COUNTIFS(新内核总表!$A$2:$A$200,A14,新内核总表!$F$2:$F$200,"<>") -> 1 | C14: =SUMIFS(新内核总表!$F$2:$F$200,新内核总表!$A$2:$A$200,A14) -> 1 | D14: =IF(B14=0,0,C14/B14) -> 1
A15: 合计·新内核完成度 | B15: =COUNTIFS(新内核总表!$F$2:$F$200,"<>") -> 49 | C15: =SUM(新内核总表!$F$2:$F$200) -> 38 | D15: =IF(B15=0,0,C15/B15) -> 0.7755102
A17: • 权重：✅=1, 🟡(门控/dry-run/空壳/未跑/半改)=0.5, ❌=0, ⏸保留(legacy,Path B不重写)=不计。
A18: • ★承重件=直接决定『双端可用/满足功能/不卡顿』:录音域 ApplyPort+ReadSeam、音频 commit、真实库切回证明。
A19: • 改状态后把总表 F 列改 1/0.5/0,本页自动重算(Excel 内重算保存)。
