Workbook

Sheet Master
A1: 层 | B1: 组件 | C1: 端 | D1: 作用 | E1: 应有文件 | F1: Codex 状态 | G1: 完成度 | H1: 对你目标优先级 | I1: 备注 / 位置
A2: 同步 | B2: 数据模型(对象/清单/哈希) | C2: 共享 | D2: canonical 统一数据模型,两端同口径 | E2: CanonicalCore.swift | F2: ✅ 已写 | G2: 1 | H2: 高 | I2: 1396行,核心
A3: 同步 | B3: diff/LWW 规划 | C3: 共享 | D3: 判定谁新谁旧、该传哪些 | E3: CanonicalSyncPlanner.swift | F3: ✅ 已写 | G3: 1 | H3: 高 | I3: 894行
A4: 同步 | B4: apply 计划 | C4: 共享 | D4: 决定如何落地 | E4: CanonicalApplyPlan.swift | F4: ✅ 已写 | G4: 1 | H4: 高 | I4: 891行
A5: 同步 | B5: apply 运行时 | C5: 共享 | D5: apply 执行编排 | E5: CanonicalApplyRuntime.swift | F5: ✅ 已写 | G5: 1 | H5: 中 | I5: 1271行
A6: 同步 | B6: 同步运行时(决策叠加) | C6: 共享 | D6: 把 canonical 决策接入被执行计划 | E6: CanonicalSyncRuntime.swift | F6: ✅ 已写 | G6: 1 | H6: 高 | I6: 604行;运行时主决策仅3 scope
A7: 同步 | B7: 库同步规划 | C7: 共享 | D7: 文件夹/学习项 diff | E7: CanonicalLibrarySyncPlanner.swift | F7: ✅ 已写 | G7: 1 | H7: 高 | I7: 607行
A8: 同步 | B8: 冲突解决 | C8: 共享 | D8: 冲突裁决 | E8: CanonicalConflictResolver.swift | F8: ✅ 已写 | G8: 1 | H8: 中 | I8: 82行
A9: 同步 | B9: 对象投影/契约 | C9: 共享 | D9: 统一对外投影 | E9: CanonicalObjectProjection / CanonicalProjectionContract | F9: ✅ 已写 | G9: 1 | H9: 高
A10: 同步 | B10: inventory 运行时/契约 | C10: 共享 | D10: 清单构建抽象 | E10: CanonicalInventoryRuntime / CanonicalInventoryBuilderContract | F10: ✅ 已写 | G10: 1 | H10: 高 | I10: 抽象在;iPhone真实builder仍@MainActor
A11: 同步 | B11: 库对象模型 | C11: 共享 | D11: 库对象规范 | E11: CanonicalLibraryObject.swift | F11: ✅ 已写 | G11: 1 | H11: 中 | I11: 365行
A12: 同步 | B12: 【修漏传】Mac apply 消费 manifest.recordings | C12: Mac | D12: 修『新文件不传』根因 | E12: RokuricsMac/StudyLibraryStore.swift(需改) | F12: ❌ 缺 | G12: 0 | H12: 高 | I12: 仍只处理folders/items/tombstones(:642-671)
A13: 同步 | B13: 【修卡顿】inventory builder 移出主线程 | C13: iPhone | D13: 修『卡顿』根因 | E13: StudyLibrarySyncCoordinator.swift(需改) | F13: ❌ 缺 | G13: 0 | H13: 高 | I13: builder仍@MainActor(:1190);假遥测count=0
A14: 同步 | B14: 域·录音元数据 | C14: 双端 | D14: 录音元信息同步 | E14: IPhone/Mac RecordingMetadata{NoCommit,Cutover}Executor | F14: 🟡 部分 | G14: 0.5 | H14: 高 | I14: 有NoCommit+Cutover;缺ReadSeam+RealApplyPort
A15: 同步 | B15: 域·库元数据 | C15: 双端 | D15: 文件夹/学习项 | E15: IPhone/Mac LibraryMetadata{NoCommit,Cutover,ReadSideSeam,RealApplyPort} | F15: ✅ 已写 | G15: 1 | H15: 高 | I15: 四件齐
A16: 同步 | B16: 域·生成产物 | C16: 双端 | D16: 转写/笔记 | E16: IPhone/Mac GeneratedArtifact{NoCommit,Cutover,ReadSideSeam,RealApplyPort} | F16: ✅ 已写 | G16: 1 | H16: 高 | I16: 四件齐
A17: 同步 | B17: 域·墓碑/冲突 | C17: 双端 | D17: 删除/冲突 | E17: IPhone/Mac TombstoneConflict{NoCommit,Cutover,ReadSideSeam,RealApplyPort} | F17: ✅ 已写 | G17: 1 | H17: 中 | I17: 四件齐
A18: 同步 | B18: 域·音频上传 | C18: 双端 | D18: 录音音频同步 | E18: IPhone/Mac AudioUploadNoCommitExecutor | F18: 🟡 部分 | G18: 0.5 | H18: 高 | I18: 仅NoCommit;缺真commit/Cutover/Read
A19: 文件 | B19: 文件运行时 | C19: 共享 | D19: 文件操作抽象 | E19: CanonicalFileRuntime.swift | F19: ✅ 已写 | G19: 1 | H19: 中 | I19: 475行
A20: 文件 | B20: 真实根原子写 | C20: 共享 | D20: 防逃逸+原子+回滚写 | E20: CanonicalRootBoundMetadataWrite.swift | F20: ✅ 已写 | G20: 1 | H20: 高 | I20: 510行
A21: 文件 | B21: 生产执行编排 | C21: 共享 | D21: 生产写编排 | E21: CanonicalProductionExecution.swift | F21: ✅ 已写 | G21: 1 | H21: 中 | I21: 538行
A22: 文件 | B22: iPhone 生产文件端口 | C22: iPhone | D22: 真实根文件读写 | E22: IPhoneCanonicalProductionFilePort.swift | F22: 🟡 部分 | G22: 0.5 | H22: 中 | I22: 默认dry-run(allowProductionRootWrites=false)
A23: 文件 | B23: iPhone 影子文件端口 | C23: iPhone | D23: 影子比对 | E23: IPhoneCanonicalShadowFilePort.swift | F23: ✅ 已写 | G23: 1 | H23: 低
A24: 文件 | B24: Mac 生产文件端口 | C24: Mac | D24: 真实根文件读写 | E24: MacCanonicalProductionFilePort.swift | F24: 🟡 部分 | G24: 0.5 | H24: 中 | I24: 默认dry-run
A25: 文件 | B25: Mac 影子文件端口 | C25: Mac | D25: 影子比对 | E25: MacCanonicalShadowFilePort.swift | F25: ✅ 已写 | G25: 1 | H25: 低
A26: 文件 | B26: legacy 文件存储(执行+兜底) | C26: 双端 | D26: 实际磁盘存储 | E26: AudioFileStore / MacRecordingFileStore / ReceivedFileStore | F26: ⏸ 保留 | H26: 中 | I26: Path B 执行肌肉,勿动
A27: 连接 | B27: 传输运行时 | C27: 共享 | D27: 传输抽象 | E27: CanonicalTransportRuntime.swift | F27: 🟡 部分 | G27: 0.5 | H27: 低 | I27: 256行,空壳
A28: 连接 | B28: 只读传输探针 | C28: 共享 | D28: 影子探测 | E28: CanonicalReadOnlyTransportProbe.swift | F28: ✅ 已写 | G28: 1 | H28: 低 | I28: 801行,仅影子
A29: 连接 | B29: 生产端口契约 | C29: 共享 | D29: 端口协议定义 | E29: CanonicalProductionPorts.swift | F29: ✅ 已写 | G29: 1 | H29: 中 | I29: 1483行
A30: 连接 | B30: iPhone 生产传输端口 | C30: iPhone | D30: 真实发请求 | E30: IPhoneCanonicalProductionTransportPort.swift | F30: 🟡 部分 | G30: 0.5 | H30: 低 | I30: sendRequest 抑制(throw networkExecutionSuppressed)
A31: 连接 | B31: iPhone 影子/探针传输 | C31: iPhone | D31: 影子 | E31: IPhoneCanonicalShadowTransportPort / IPhoneCanonicalLiveReadOnlyTransportProbe | F31: ✅ 已写 | G31: 1 | H31: 低
A32: 连接 | B32: Mac 生产传输端口 | C32: Mac | D32: 真实发请求 | E32: MacCanonicalProductionTransportPort.swift | F32: 🟡 部分 | G32: 0.5 | H32: 低 | I32: 抑制
A33: 连接 | B33: Mac 影子/探针传输 | C33: Mac | D33: 影子 | E33: MacCanonicalShadowTransportPort / MacCanonicalLiveReadOnlyTransportProbeAudit | F33: ✅ 已写 | G33: 1 | H33: 低
A34: 连接 | B34: legacy 连接(TLS/配对/HMAC/server) | C34: 双端 | D34: 真实安全传输 | E34: SecureLocalHTTPSServer / RequestVerifier / PairingManager / PairedDeviceStore / SelfSignedCertificateBuilder / SecureMacUploadClient | F34: ⏸ 保留 | H34: 高 | I34: 可靠且安全,Path B 勿重写
A35: 上传 | B35: 上传运行时 | C35: 共享 | D35: 上传抽象 | E35: CanonicalUploadRuntime.swift | F35: 🟡 部分 | G35: 0.5 | H35: 低 | I35: 473行,空壳
A36: 上传 | B36: 音频上传 cutover 模型 | C36: 共享 | D36: 上传迁移模型 | E36: CanonicalAudioUploadCutover.swift | F36: ✅ 已写 | G36: 1 | H36: 中 | I36: 1507行(模型,非执行)
A37: 上传 | B37: 音频上传 runtime commit 模型 | C37: 共享 | D37: 上传提交模型 | E37: CanonicalAudioUploadRuntimeCommit.swift | F37: ✅ 已写 | G37: 1 | H37: 中 | I37: 1560行(模型)
A38: 上传 | B38: 传输状态机 | C38: 共享 | D38: 上传状态 | E38: CanonicalTransferStateMachine.swift | F38: ✅ 已写 | G38: 1 | H38: 中 | I38: 192行
A39: 上传 | B39: iPhone 生产上传端口 | C39: iPhone | D39: 真实分块上传 | E39: IPhoneCanonicalProductionUploadPort.swift | F39: 🟡 部分 | G39: 0.5 | H39: 低 | I39: fakeLedger 空壳
A40: 上传 | B40: iPhone 音频 NoCommit 执行器 | C40: iPhone | D40: 不提交演练 | E40: IPhoneAudioUploadNoCommitExecutor.swift | F40: ✅ 已写 | G40: 1 | H40: 中
...

Sheet DomainMatrix
A1: 同步域 | B1: NoCommit 执行器 | C1: Cutover 执行器 | D1: 真实 ApplyPort | E1: 读侧 Seam | F1: 真 commit/落地 | G1: 共享 cutover 模型 | H1: 就绪度(4-5件)
A2: 录音元数据 | B2: ✅ 双端 | C2: ✅ 双端 | D2: ❌ 缺 | E2: ❌ 缺 | F2: —(走ExecutionShadow) | G2: ✅ | H2: 🟡 2/4
A3: 库元数据 | B3: ✅ 双端 | C3: ✅ 双端 | D3: ✅ 双端 | E3: ✅ 双端 | F3: — | G3: ✅ | H3: ✅ 4/4
A4: 生成产物 | B4: ✅ 双端 | C4: ✅ 双端 | D4: ✅ 双端 | E4: ✅ 双端 | F4: — | G4: ✅ | H4: ✅ 4/4
A5: 墓碑/冲突 | B5: ✅ 双端 | C5: ✅ 双端 | D5: ✅ 双端 | E5: ✅ 双端 | F5: — | G5: ✅ | H5: ✅ 4/4
A6: 音频上传 | B6: ✅ 双端 | C6: ❌ 缺 | D6: ❌ 缺 | E6: ❌ 缺 | F6: ❌ 缺真commit | G6: ✅(模型) | H6: 🟡 1/5

Sheet Summary
A1: 层 | B1: 应建组件数 | C1: 已完成(加权) | D1: 完成度 %
A2: 文件 | B2: =COUNTIFS(Master!$A$2:$A$200,A2,Master!$G$2:$G$200,"<>") -> 7 | C2: =SUMIFS(Master!$G$2:$G$200,Master!$A$2:$A$200,A2) -> 6 | D2: =IF(B2=0,0,C2/B2) -> 0.85714286
A3: 连接 | B3: =COUNTIFS(Master!$A$2:$A$200,A3,Master!$G$2:$G$200,"<>") -> 7 | C3: =SUMIFS(Master!$G$2:$G$200,Master!$A$2:$A$200,A3) -> 5.5 | D3: =IF(B3=0,0,C3/B3) -> 0.78571429
A4: 上传 | B4: =COUNTIFS(Master!$A$2:$A$200,A4,Master!$G$2:$G$200,"<>") -> 11 | C4: =SUMIFS(Master!$G$2:$G$200,Master!$A$2:$A$200,A4) -> 7.5 | D4: =IF(B4=0,0,C4/B4) -> 0.68181818
A5: 同步 | B5: =COUNTIFS(Master!$A$2:$A$200,A5,Master!$G$2:$G$200,"<>") -> 17 | C5: =SUMIFS(Master!$G$2:$G$200,Master!$A$2:$A$200,A5) -> 14 | D5: =IF(B5=0,0,C5/B5) -> 0.82352941
A6: 接口 | B6: =COUNTIFS(Master!$A$2:$A$200,A6,Master!$G$2:$G$200,"<>") -> 9 | C6: =SUMIFS(Master!$G$2:$G$200,Master!$A$2:$A$200,A6) -> 8.5 | D6: =IF(B6=0,0,C6/B6) -> 0.94444444
A7: UI | B7: =COUNTIFS(Master!$A$2:$A$200,A7,Master!$G$2:$G$200,"<>") -> 6 | C7: =SUMIFS(Master!$G$2:$G$200,Master!$A$2:$A$200,A7) -> 5 | D7: =IF(B7=0,0,C7/B7) -> 0.83333333
A8: 合计 / canonical 面完成度 | B8: =COUNTIFS(Master!$G$2:$G$200,"<>") -> 57 | C8: =SUM(Master!$G$2:$G$200) -> 46.5 | D8: =IF(B8=0,0,C8/B8) -> 0.81578947
A9: 其中·高优先级(对你目标的有效进度) | B9: =COUNTIFS(Master!$H$2:$H$200,"高",Master!$G$2:$G$200,"<>") -> 21 | C9: =SUMIFS(Master!$G$2:$G$200,Master!$H$2:$H$200,"高") -> 15.5 | D9: =IF(B9=0,0,C9/B9) -> 0.73809524
A11: 图例 / 口径
A12: • 完成度权重：✅已写=1, 🟡部分(空壳/仅模型/未真机证)=0.5, ❌缺=0, ⏸保留(legacy,Path B 勿动)=不计入分母。
A13: • 两把尺子：① canonical 面完成度=所有应建组件的加权完成；② 高优先级完成度=只看对你三条标准关键的项,更接近『真实可用进度』。
A14: • 改状态后：把 Master 表 G 列改成 1/0.5/0,本页自动重算(需在 Excel 中重算/保存)。
A15: • ⏸ 行不计入进度:它们是 legacy 执行肌肉与兜底,按路线图 Path B 保留不重写。
